<?xml version="1.0" encoding="UTF-8"?><record_update table="sys_ui_message">
    <sys_ui_message action="INSERT_OR_UPDATE">
        <application/>
        <code/>
        <commented_message/>
        <key>exception occured at line number:{0} while parsing object with id: {1} : {2}</key>
        <language>uk</language>
        <message>Виняток стався у рядку під номером: {0} під час аналізу об'єкта з ідентифікатором: {1}: {2}.</message>
        <sys_class_name>sys_ui_message</sys_class_name>
        <sys_created_by>bogdan.felinskyi</sys_created_by>
        <sys_created_on>2022-03-23 17:35:56</sys_created_on>
        <sys_id>c17e78a31b96c910c069657bab4bcb3a</sys_id>
        <sys_mod_count>0</sys_mod_count>
        <sys_name>exception occured at line number:{0} while parsing object with id: {1} : {2}</sys_name>
        <sys_package display_value="I18N: Ukrainian Translations" source="176ebda287b38910f4b131570cbb3551">176ebda287b38910f4b131570cbb3551</sys_package>
        <sys_policy/>
        <sys_scope display_value="I18N: Ukrainian Translations">176ebda287b38910f4b131570cbb3551</sys_scope>
        <sys_update_name>sys_ui_message_c17e78a31b96c910c069657bab4bcb3a</sys_update_name>
        <sys_updated_by>bogdan.felinskyi</sys_updated_by>
        <sys_updated_on>2022-03-23 17:35:56</sys_updated_on>
    </sys_ui_message>
</record_update>
